Workbook

Sheet Clarias_Bioplan
A1: DAYS | C1: 1 | D1: 2 | E1: 3 | F1: 4 | G1: 5 | H1: 6 | I1: 7 | J1: 8 | K1: 9 | L1: 10 | M1: 11 | N1: 12 | O1: 13 | P1: 14 | Q1: 15 | R1: 16 | S1: 17 | T1: 18 | U1: 19 | V1: 20 | W1: 21 | X1: 22 | Y1: 23 | Z1: 24 | AA1: 25 | AB1: 26 | AC1: 27 | AD1: 28 | AE1: 29 | AF1: 30 | AG1: 31 | AH1: 32 | AI1: 33 | AJ1: 34 | AK1: 35 | AL1: 36 | AM1: 37 | AN1: 38 | AO1: 39 | AP1: 40 | AQ1: 41 | AR1: 42 | AS1: 43 | AT1: 44 | AU1: 45 | AV1: 46 | AW1: 47 | AX1: 48 | AY1: 49 | AZ1: 50 | BA1: 51 | BB1: 52 | BC1: 53 | BD1: 54 | BE1: 55 | BF1: 56 | BG1: 57 | BH1: 58 | BI1: 59 | BJ1: 60 | BK1: 61 | BL1: 62 | BM1: 63 | BN1: 64 | BO1: 65 | BP1: 66 | BQ1: 67 | BR1: 68 | BS1: 69 | BT1: 70 | BU1: 71 | BV1: 72 | BW1: 73 | BX1: 74 | BY1: 75 | BZ1: 76 | CA1: 77 | CB1: 78 | CC1: 79 | CD1: 80 | CE1: 81 | CF1: 82 | CG1: 83 | CH1: 84 | CI1: 85 | CJ1: 86 | CK1: 87 | CL1: 88 | CM1: 89 | CN1: 90 | CO1: 91 | CP1: 92 | CQ1: 93 | CR1: 94 | CS1: 95 | CT1: 96 | CU1: 97 | CV1: 98 | CW1: 99 | CX1: 100 | CY1: 101 | CZ1: 102 | DA1: 103 | DB1: 104 | DC1: 105 | DD1: 106 | DE1: 107 | DF1: 108 | DG1: 109 | DH1: 110 | DI1: 111 | DJ1: 112 | DK1: 113 | DL1: 114 | DM1: 115 | DN1: 116 | DO1: 117 | DP1: 118 | DQ1: 119 | DR1: 120 | DS1: 121 | DT1: 122 | DU1: 123 | DV1: 124 | DW1: 125 | DX1: 126 | DY1: 127 | DZ1: 128 | EA1: 129 | EB1: 130 | EC1: 131 | ED1: 132 | EE1: 133 | EF1: 134 | EG1: 135 | EH1: 136 | EI1: 137 | EJ1: 138 | EK1: 139 | EL1: 140 | EM1: 141 | EN1: 142 | EO1: 143 | EP1: 144 | EQ1: 145 | ER1: 146 | ES1: 147 | ET1: 148 | EU1: 149 | EV1: 150 | EW1: 151 | EX1: 152 | EY1: 153 | EZ1: 154 | FA1: 155 | FB1: 156 | FC1: 157 | FD1: 158 | FE1: 159 | FF1: 160 | FG1: 161 | FH1: 162 | FI1: 163 | FJ1: 164 | FK1: 165 | FL1: 166 | FM1: 167 | FN1: 168 | FO1: 169 | FP1: 170 | FQ1: 171 | FR1: 172 | FS1: 173 | FT1: 174 | FU1: 175 | FV1: 176 | FW1: 177 | FX1: 178 | FY1: 179 | FZ1: 180 | GA1: 181 | GB1: 182 | GC1: 183 | GD1: 184 | GE1: 185 | GF1: 186 | GG1: 187 | GH1: 188 | GI1: 189 | GJ1: 190 | GK1: 191 | GL1: 192 | GM1: 193 | GN1: 194 | GO1: 195 | GP1: 196 | GQ1: 197 | GR1: 198 | GS1: 199 | GT1: 200 | GU1: 201 | GV1: 202 | GW1: 203 | GX1: 204 | GY1: 205 | GZ1: 206 | HA1: 207 | HB1: 208 | HC1: 209 | HD1: 210 | HE1: 211 | HF1: 212 | HG1: 213 | HH1: 214 | HI1: 215 | HJ1: 216 | HK1: 217 | HL1: 218 | HM1: 219 | HN1: 220 | HO1: 221 | HP1: 222 | HQ1: 223 | HR1: 224 | HS1: 225 | HT1: 226 | HU1: 227 | HV1: 228 | HW1: 229 | HX1: 230 | HY1: 231 | HZ1: 232 | IA1: 233 | IB1: 234 | IC1: 235 | ID1: 236 | IE1: 237 | IF1: 238 | IG1: 239 | IH1: 240 | II1: 241 | IJ1: 242 | IK1: 243 | IL1: 244 | IM1: 245 | IN1: 246 | IO1: 247 | IP1: 248 | IQ1: 249 | IR1: 250 | IS1: 251 | IT1: 252 | IU1: 253 | IV1: 254 | IW1: 255 | IX1: 256 | IY1: 257 | IZ1: 258 | JA1: 259 | JB1: 260 | JC1: 261 | JD1: 262 | JE1: 263 | JF1: 264 | JG1: 265 | JH1: 266 | JI1: 267 | JJ1: 268 | JK1: 269 | JL1: 270 | JM1: 271 | JN1: 272 | JO1: 273 | JP1: 274 | JQ1: 275 | JR1: 276 | JS1: 277 | JT1: 278 | JU1: 279 | JV1: 280 | JW1: 281 | JX1: 282 | JY1: 283 | JZ1: 284 | KA1: 285 | KB1: 286 | KC1: 287 | KD1: 288 | KE1: 289 | KF1: 290 | KG1: 291 | KH1: 292 | KI1: 293 | KJ1: 294 | KK1: 295 | KL1: 296 | KM1: 297 | KN1: 298 | KO1: 299 | KP1: 300 | KQ1: 301 | KR1: 302 | KS1: 303 | KT1: 304 | KU1: 305 | KV1: 306 | KW1: 307 | KX1: 308 | KY1: 309 | KZ1: 310 | LA1: 311 | LB1: 312 | LC1: 313 | LD1: 314 | LE1: 315 | LF1: 316 | LG1: 317 | LH1: 318 | LI1: 319 | LJ1: 320 | LK1: 321 | LL1: 322 | LM1: 323 | LN1: 324 | LO1: 325 | LP1: 326 | LQ1: 327 | LR1: 328 | LS1: 329 | LT1: 330 | LU1: 331 | LV1: 332 | LW1: 333 | LX1: 334 | LY1: 335 | LZ1: 336 | MA1: 337 | MB1: 338 | MC1: 339 | MD1: 340 | ME1: 341 | MF1: 342 | MG1: 343 | MH1: 344 | MI1: 345 | MJ1: 346 | MK1: 347 | ML1: 348 | MM1: 349 | MN1: 350 | MO1: 351 | MP1: 352 | MQ1: 353 | MR1: 354 | MS1: 355 | MT1: 356 | MU1: 357 | MV1: 358 | MW1: 359 | MX1: 360 | MY1: 361 | MZ1: 362 | NA1: 363 | NB1: 364 | NC1: 365 | ND1: 366 | NE1: 367 | NF1: 368 | NG1: 369 | NH1: 370 | NI1: 371 | NJ1: 372 | NK1: 373 | NL1: 374 | NM1: 375 | NN1: 376 | NO1: 377 | NP1: 378 | NQ1: 379 | NR1: 380 | NS1: 381 | NT1: 382 | NU1: 383 | NV1: 384 | NW1: 385 | NX1: 386 | NY1: 387 | NZ1: 388 | OA1: 389 | OB1: 390 | OC1: 391 | OD1: 392 | OE1: 393 | OF1: 394 | OG1: 395 | OH1: 396 | OI1: 397 | OJ1: 398 | OK1: 399 | OL1: 400 | OM1: 401 | ON1: 402 | OO1: 403 | OP1: 404 | OQ1: 405 | OR1: 406 | OS1: 407 | OT1: 408 | OU1: 409 | OV1: 410 | OW1: 411 | OX1: 412 | OY1: 413 | OZ1: 414 | PA1: 415 | PB1: 416 | PC1: 417 | PD1: 418 | PE1: 419 | PF1: 420 | PG1: 421 | PH1: 422 | PI1: 423 | PJ1: 424 | PK1: 425 | PL1: 426 | PM1: 427 | PN1: 428 | PO1: 429 | PP1: 430 | PQ1: 431 | PR1: 432 | PS1: 433 | PT1: 434 | PU1: 435 | PV1: 436 | PW1: 437 | PX1: 438 | PY1: 439 | PZ1: 440 | QA1: 441 | QB1: 442 | QC1: 443 | QD1: 444 | QE1: 445 | QF1: 446 | QG1: 447 | QH1: 448 | QI1: 449 | QJ1: 450 | QK1: 451 | QL1: 452 | QM1: 453 | QN1: 454 | QO1: 455 | QP1: 456 | QQ1: 457 | QR1: 458 | QS1: 459 | QT1: 460 | QU1: 461 | QV1: 462 | QW1: 463 | QX1: 464 | QY1: 465 | QZ1: 466 | RA1: 467 | RB1: 468 | RC1: 469 | RD1: 470 | RE1: 471 | RF1: 472 | RG1: 473 | RH1: 474 | RI1: 475 | RJ1: 476 | RK1: 477 | RL1: 478 | RM1: 479 | RN1: 480 | RO1: 481 | RP1: 482 | RQ1: 483 | RR1: 484 | RS1: 485 | RT1: 486 | RU1: 487 | RV1: 488 | RW1: 489 | RX1: 490 | RY1: 491 | RZ1: 492 | SA1: 493 | SB1: 494 | SC1: 495 | SD1: 496 | SE1: 497 | SF1: 498 | SG1: 499 | SH1: 500 | SI1: 501 | SJ1: 502 | SK1: 503 | SL1: 504 | SM1: 505 | SN1: 506 | SO1: 507 | SP1: 508 | SQ1: 509 | SR1: 510 | SS1: 511 | ST1: 512 | SU1: 513 | SV1: 514 | SW1: 515 | SX1: 516 | SY1: 517 | SZ1: 518 | TA1: 519 | TB1: 520 | TC1: 521 | TD1: 522 | TE1: 523 | TF1: 524 | TG1: 525 | TH1: 526 | TI1: 527 | TJ1: 528 | TK1: 529 | TL1: 530 | TM1: 531 | TN1: 532 | TO1: 533 | TP1: 534 | TQ1: 535 | TR1: 536 | TS1: 537 | TT1: 538 | TU1: 539 | TV1: 540 | TW1: 541 | TX1: 542 | TY1: 543 | TZ1: 544 | UA1: 545 | UB1: 546 | UC1: 547 | UD1: 548 | UE1: 549 | UF1: 550 | UG1: 551 | UH1: 552 | UI1: 553 | UJ1: 554 | UK1: 555 | UL1: 556 | UM1: 557 | UN1: 558 | UO1: 559 | UP1: 560 | UQ1: 561 | UR1: 562 | US1: 563 | UT1: 564 | UU1: 565 | UV1: 566 | UW1: 567 | UX1: 568 | UY1: 569 | UZ1: 570 | VA1: 571 | VB1: 572 | VC1: 573 | VD1: 574 | VE1: 575 | VF1: 576 | VG1: 577 | VH1: 578 | VI1: 579 | VJ1: 580 | VK1: 581 | VL1: 582 | VM1: 583 | VN1: 584 | VO1: 585 | VP1: 586 | VQ1: 587 | VR1: 588 | VS1: 589 | VT1: 590 | VU1: 591 | VV1: 592 | VW1: 593 | VX1: 594 | VY1: 595 | VZ1: 596 | WA1: 597 | WB1: 598 | WC1: 599 | WD1: 600 | WE1: 601 | WF1: 602 | WG1: 603 | WH1: 604 | WI1: 605 | WJ1: 606 | WK1: 607 | WL1: 608 | WM1: 609 | WN1: 610 | WO1: 611 | WP1: 612 | WQ1: 613 | WR1: 614 | WS1: 615 | WT1: 616 | WU1: 617 | WV1: 618 | WW1: 619 | WX1: 620 | WY1: 621 | WZ1: 622 | XA1: 623 | XB1: 624 | XC1: 625 | XD1: 626 | XE1: 627 | XF1: 628 | XG1: 629 | XH1: 630 | XI1: 631 | XJ1: 632 | XK1: 633 | XL1: 634 | XM1: 635 | XN1: 636 | XO1: 637 | XP1: 638 | XQ1: 639 | XR1: 640 | XS1: 641 | XT1: 642 | XU1: 643 | XV1: 644 | XW1: 645 | XX1: 646 | XY1: 647 | XZ1: 648 | YA1: 649 | YB1: 650 | YC1: 651 | YD1: 652 | YE1: 653 | YF1: 654 | YG1: 655 | YH1: 656 | YI1: 657 | YJ1: 658 | YK1: 659 | YL1: 660 | YM1: 661 | YN1: 662 | YO1: 663 | YP1: 664 | YQ1: 665 | YR1: 666 | YS1: 667 | YT1: 668 | YU1: 669 | YV1: 670 | YW1: 671 | YX1: 672 | YY1: 673 | YZ1: 674 | ZA1: 675 | ZB1: 676 | ZC1: 677 | ZD1: 678 | ZE1: 679 | ZF1: 680 | ZG1: 681 | ZH1: 682 | ZI1: 683 | ZJ1: 684 | ZK1: 685 | ZL1: 686 | ZM1: 687 | ZN1: 688 | ZO1: 689 | ZP1: 690 | ZQ1: 691 | ZR1: 692 | ZS1: 693 | ZT1: 694 | ZU1: 695 | ZV1: 696 | ZW1: 697 | ZX1: 698 | ZY1: 699 | ZZ1: 700 | AAA1: 701 | AAB1: 702 | AAC1: 703 | AAD1: 704 | AAE1: 705 | AAF1: 706 | AAG1: 707 | AAH1: 708 | AAI1: 709 | AAJ1: 710 | AAK1: 711 | AAL1: 712 | AAM1: 713 | AAN1: 714 | AAO1: 715 | AAP1: 716 | AAQ1: 717 | AAR1: 718 | AAS1: 719 | AAT1: 720 | AAU1: 721 | AAV1: 722 | AAW1: 723 | AAX1: 724 | AAY1: 725 | AAZ1: 726 | ABA1: 727 | ABB1: 728 | ABC1: 729 | ABD1: 730 | ABE1: 731 | ABF1: 732 | ABG1: 733 | ABH1: 734 | ABI1: 735 | ABJ1: 736 | ABK1: 737 | ABL1: 738 | ABM1: 739 | ABN1: 740 | ABO1: 741 | ABP1: 742 | ABQ1: 743 | ABR1: 744 | ABS1: 745 | ABT1: 746 | ABU1: 747 | ABV1: 748 | ABW1: 749 | ABX1: 750 | ABY1: 751 | ABZ1: 752 | ACA1: 753 | ACB1: 754 | ACC1: 755 | ACD1: 756 | ACE1: 757 | ACF1: 758 | ACG1: 759 | ACH1: 760 | ACI1: 761 | ACJ1: 762 | ACK1: 763 | ACL1: 764 | ACM1: 765 | ACN1: 766 | ACO1: 767 | ACP1: 768 | ACQ1: 769 | ACR1: 770 | ACS1: 771 | ACT1: 772 | ACU1: 773 | ACV1: 774 | ACW1: 775 | ACX1: 776 | ACY1: 777 | ACZ1: 778 | ADA1: 779 | ADB1: 780 | ADC1: 781 | ADD1: 782 | ADE1: 783 | ADF1: 784 | ADG1: 785 | ADH1: 786 | ADI1: 787 | ADJ1: 788 | ADK1: 789 | ADL1: 790 | ADM1: 791 | ADN1: 792 | ADO1: 793 | ADP1: 794 | ADQ1: 795 | ADR1: 796 | ADS1: 797 | ADT1: 798 | ADU1: 799 | ADV1: 800 | ADW1: 801 | ADX1: 802 | ADY1: 803 | ADZ1: 804 | AEA1: 805 | AEB1: 806 | AEC1: 807 | AED1: 808 | AEE1: 809 | AEF1: 810 | AEG1: 811 | AEH1: 812 | AEI1: 813 | AEJ1: 814 | AEK1: 815 | AEL1: 816 | AEM1: 817 | AEN1: 818 | AEO1: 819 | AEP1: 820 | AEQ1: 821 | AER1: 822 | AES1: 823 | AET1: 824 | AEU1: 825 | AEV1: 826 | AEW1: 827 | AEX1: 828 | AEY1: 829 | AEZ1: 830 | AFA1: 831 | AFB1: 832 | AFC1: 833 | AFD1: 834 | AFE1: 835 | AFF1: 836 | AFG1: 837 | AFH1: 838 | AFI1: 839 | AFJ1: 840 | AFK1: 841 | AFL1: 842 | AFM1: 843 | AFN1: 844 | AFO1: 845 | AFP1: 846 | AFQ1: 847 | AFR1: 848 | AFS1: 849 | AFT1: 850 | AFU1: 851 | AFV1: 852 | AFW1: 853 | AFX1: 854 | AFY1: 855 | AFZ1: 856 | AGA1: 857 | AGB1: 858 | AGC1: 859 | AGD1: 860 | AGE1: 861 | AGF1: 862 | AGG1: 863 | AGH1: 864 | AGI1: 865 | AGJ1: 866 | AGK1: 867 | AGL1: 868 | AGM1: 869 | AGN1: 870 | AGO1: 871 | AGP1: 872 | AGQ1: 873 | AGR1: 874 | AGS1: 875 | AGT1: 876 | AGU1: 877 | AGV1: 878 | AGW1: 879 | AGX1: 880 | AGY1: 881 | AGZ1: 882 | AHA1: 883 | AHB1: 884 | AHC1: 885 | AHD1: 886 | AHE1: 887 | AHF1: 888 | AHG1: 889 | AHH1: 890 | AHI1: 891 | AHJ1: 892 | AHK1: 893 | AHL1: 894 | AHM1: 895 | AHN1: 896 | AHO1: 897 | AHP1: 898 | AHQ1: 899 | AHR1: 900 | AHS1: 901 | AHT1: 902 | AHU1: 903 | AHV1: 904 | AHW1: 905 | AHX1: 906 | AHY1: 907 | AHZ1: 908 | AIA1: 909 | AIB1: 910 | AIC1: 911 | AID1: 912 | AIE1: 913 | AIF1: 914 | AIG1: 915 | AIH1: 916 | AII1: 917 | AIJ1: 918 | AIK1: 919 | AIL1: 920 | AIM1: 921 | AIN1: 922 | AIO1: 923 | AIP1: 924 | AIQ1: 925 | AIR1: 926 | AIS1: 927 | AIT1: 928 | AIU1: 929 | AIV1: 930 | AIW1: 931 | AIX1: 932 | AIY1: 933 | AIZ1: 934 | AJA1: 935
A2: BIOMASS TOTAL SYSTEM (KG) | C2: =C34+C47+C60+C73+C86+C99+C112+C125+C138+C151+C164+C177+C190 -> 2.5 | D2: =D34+D47+D60+D73+D86+D99+D112+D125+D138+D151+D164+D177+D190 -> 2.7458929 | E2: =E34+E47+E60+E73+E86+E99+E112+E125+E138+E151+E164+E177+E190 -> 3.0145 | F2: =F34+F47+F60+F73+F86+F99+F112+F125+F138+F151+F164+F177+F190 -> 3.3030458 | G2: =G34+G47+G60+G73+G86+G99+G112+G125+G138+G151+G164+G177+G190 -> 3.6180521 | H2: =H34+H47+H60+H73+H86+H99+H112+H125+H138+H151+H164+H177+H190 -> 3.960561 | I2: =I34+I47+I60+I73+I86+I99+I112+I125+I138+I151+I164+I177+I190 -> 4.3261618 | J2: =J34+J47+J60+J73+J86+J99+J112+J125+J138+J151+J164+J177+J190 -> 4.7232736 | ... AJA2: =AJA34+AJA47+AJA60+AJA73+AJA86+AJA99+AJA112+AJA125+AJA138+AJA151+AJA164+AJA177+AJA190 -> 0
A3: REARING DENSITY TOTAL SYSTEM (KG/M3) | C3: =(C34+C47+C60+C73+C86+C99+C112+C125+C138+C151+C164+C177+C190)/('DATA SECTION'!$C$3+'DATA SECTION'!$C$4+'DATA SECTION'!$C$5) -> 0.69444444 | D3: =(D34+D47+D60+D73+D86+D99+D112+D125+D138+D151+D164+D177+D190)/('DATA SECTION'!$C$3+'DATA SECTION'!$C$4+'DATA SECTION'!$C$5) -> 0.76274802 | E3: =(E34+E47+E60+E73+E86+E99+E112+E125+E138+E151+E164+E177+E190)/('DATA SECTION'!$C$3+'DATA SECTION'!$C$4+'DATA SECTION'!$C$5) -> 0.83736112 | F3: =(F34+F47+F60+F73+F86+F99+F112+F125+F138+F151+F164+F177+F190)/('DATA SECTION'!$C$3+'DATA SECTION'!$C$4+'DATA SECTION'!$C$5) -> 0.91751273 | G3: =(G34+G47+G60+G73+G86+G99+G112+G125+G138+G151+G164+G177+G190)/('DATA SECTION'!$C$3+'DATA SECTION'!$C$4+'DATA SECTION'!$C$5) -> 1.0050145 | H3: =(H34+H47+H60+H73+H86+H99+H112+H125+H138+H151+H164+H177+H190)/('DATA SECTION'!$C$3+'DATA SECTION'!$C$4+'DATA SECTION'!$C$5) -> 1.1001558 | I3: =(I34+I47+I60+I73+I86+I99+I112+I125+I138+I151+I164+I177+I190)/('DATA SECTION'!$C$3+'DATA SECTION'!$C$4+'DATA SECTION'!$C$5) -> 1.2017116 | J3: =(J34+J47+J60+J73+J86+J99+J112+J125+J138+J151+J164+J177+J190)/('DATA SECTION'!$C$3+'DATA SECTION'!$C$4+'DATA SECTION'!$C$5) -> 1.3120204 | ... AJA3: =(AJA34+AJA47+AJA60+AJA73+AJA86+AJA99+AJA112+AJA125+AJA138+AJA151+AJA164+AJA177+AJA190)/('DATA SECTION'!$C$3+'DATA SECTION'!$C$4+'DATA SECTION'!$C$5) -> 0
A4: TOTAL FEED SYSTEM (KG/D) | C4: =C36+C49+C62+C75+C88+C101+C114+C127+C140+C153+C166+C179+C192 -> 0.1405 | D4: =D36+D49+D62+D75+D88+D101+D114+D127+D140+D153+D166+D179+D192 -> 0.15349541 | E4: =E36+E49+E62+E75+E88+E101+E114+E127+E140+E153+E166+E179+E192 -> 0.16790765 | F4: =F36+F49+F62+F75+F88+F101+F114+F127+F140+F153+F166+F179+F192 -> 0.18331904 | G4: =G36+G49+G62+G75+G88+G101+G114+G127+G140+G153+G166+G179+G192 -> 0.19935467 | H4: =H36+H49+H62+H75+H88+H101+H114+H127+H140+H153+H166+H179+H192 -> 0.21664269 | I4: =I36+I49+I62+I75+I88+I101+I114+I127+I140+I153+I166+I179+I192 -> 0.2353432 | J4: =J36+J49+J62+J75+J88+J101+J114+J127+J140+J153+J166+J179+J192 -> 0.25505678 | ... AJA4: =AJA36+AJA49+AJA62+AJA75+AJA88+AJA101+AJA114+AJA127+AJA140+AJA153+AJA166+AJA179+AJA192 -> 0
A5: DAILY FEED RATION TOTAL SYSTEM (%) | C5: =C4/C2 -> 0.0562 | D5: =D4/D2 -> 0.0559 | E5: =E4/E2 -> 0.0557 | F5: =F4/F2 -> 0.0555 | G5: =G4/G2 -> 0.0551 | H5: =H4/H2 -> 0.0547 | I5: =I4/I2 -> 0.0544 | J5: =J4/J2 -> 0.054 | ... AJA5: =AJA4/AJA2 -> #DIV/0!
A6: HARVEST (KG/D) | C6: =C30*C33+C43*C46+C56*C59+C69*C72+C82*C85+C95*C98+C108*C111+C121*C124+C134*C137+C147*C150+C160*C163+C173*C176+C186*C189 -> 0 | D6: =D30*D33+D43*D46+D56*D59+D69*D72+D82*D85+D95*D98+D108*D111+D121*D124+D134*D137+D147*D150+D160*D163+D173*D176+D186*D189 -> 0 | E6: =E30*E33+E43*E46+E56*E59+E69*E72+E82*E85+E95*E98+E108*E111+E121*E124+E134*E137+E147*E150+E160*E163+E173*E176+E186*E189 -> 0 | F6: =F30*F33+F43*F46+F56*F59+F69*F72+F82*F85+F95*F98+F108*F111+F121*F124+F134*F137+F147*F150+F160*F163+F173*F176+F186*F189 -> 0 | G6: =G30*G33+G43*G46+G56*G59+G69*G72+G82*G85+G95*G98+G108*G111+G121*G124+G134*G137+G147*G150+G160*G163+G173*G176+G186*G189 -> 0 | H6: =H30*H33+H43*H46+H56*H59+H69*H72+H82*H85+H95*H98+H108*H111+H121*H124+H134*H137+H147*H150+H160*H163+H173*H176+H186*H189 -> 0 | I6: =I30*I33+I43*I46+I56*I59+I69*I72+I82*I85+I95*I98+I108*I111+I121*I124+I134*I137+I147*I150+I160*I163+I173*I176+I186*I189 -> 0 | J6: =J30*J33+J43*J46+J56*J59+J69*J72+J82*J85+J95*J98+J108*J111+J121*J124+J134*J137+J147*J150+J160*J163+J173*J176+J186*J189 -> 0 | ... AJA6: =AJA30*AJA33+AJA43*AJA46+AJA56*AJA59+AJA69*AJA72+AJA82*AJA85+AJA95*AJA98+AJA108*AJA111+AJA121*AJA124+AJA134*AJA137+AJA147*AJA150+AJA160*AJA163+AJA173*AJA176+AJA186*AJA189 -> 0
A7: NaOH (KG/DAY) | C7: =(C4*40)/1000 -> 0.00562 | D7: =(D4*40)/1000 -> 0.0061398164 | E7: =(E4*40)/1000 -> 0.006716306 | F7: =(F4*40)/1000 -> 0.0073327618 | G7: =(G4*40)/1000 -> 0.0079741869 | H7: =(H4*40)/1000 -> 0.0086657076 | I7: =(I4*40)/1000 -> 0.0094137281 | J7: =(J4*40)/1000 -> 0.010202271 | ... AJA7: =(AJA4*40)/1000 -> 0
A8: LOW DM FEED - DM FED | C8: =C4*$AJ$16 -> 0.12645 | D8: =D4*$AJ$16 -> 0.13814587 | E8: =E4*$AJ$16 -> 0.15111689 | F8: =F4*$AJ$16 -> 0.16498714 | G8: =G4*$AJ$16 -> 0.1794192 | H8: =H4*$AJ$16 -> 0.19497842 | I8: =I4*$AJ$16 -> 0.21180888 | J8: =J4*$AJ$16 -> 0.2295511 | ... AJA8: =AJA4*$AJ$16 -> 0
A9: COLLECTED FECES DM - LOW DIGEST | C9: =C8*(100%-$AJ$18)*$AJ$20 -> 0.028767375 | D9: =D8*(100%-$AJ$18)*$AJ$20 -> 0.031428185 | E9: =E8*(100%-$AJ$18)*$AJ$20 -> 0.034379092 | F9: =F8*(100%-$AJ$18)*$AJ$20 -> 0.037534574 | G9: =G8*(100%-$AJ$18)*$AJ$20 -> 0.040817869 | H9: =H8*(100%-$AJ$18)*$AJ$20 -> 0.044357591 | I9: =I8*(100%-$AJ$18)*$AJ$20 -> 0.048186521 | J9: =J8*(100%-$AJ$18)*$AJ$20 -> 0.052222875 | ... AJA9: =AJA8*(100%-$AJ$18)*$AJ$20 -> 0
A10: COLLECTED FECES DM - HIGH DIGEST | C10: =C8*(100%-$AJ$19)*$AJ$20 -> 0.020548125 | D10: =D8*(100%-$AJ$19)*$AJ$20 -> 0.022448704 | E10: =E8*(100%-$AJ$19)*$AJ$20 -> 0.024556494 | F10: =F8*(100%-$AJ$19)*$AJ$20 -> 0.02681041 | G10: =G8*(100%-$AJ$19)*$AJ$20 -> 0.029155621 | H10: =H8*(100%-$AJ$19)*$AJ$20 -> 0.031683993 | I10: =I8*(100%-$AJ$19)*$AJ$20 -> 0.034418943 | J10: =J8*(100%-$AJ$19)*$AJ$20 -> 0.037302053 | ... AJA10: =AJA8*(100%-$AJ$19)*$AJ$20 -> 0
A11: HIGH DM FEED - DM FED | C11: =C4*$AJ$17 -> 0.133475 | D11: =D4*$AJ$17 -> 0.14582064 | E11: =E4*$AJ$17 -> 0.15951227 | F11: =F4*$AJ$17 -> 0.17415309 | G11: =G4*$AJ$17 -> 0.18938694 | H11: =H4*$AJ$17 -> 0.20581055 | I11: =I4*$AJ$17 -> 0.22357604 | J11: =J4*$AJ$17 -> 0.24230394 | ... AJA11: =AJA4*$AJ$17 -> 0
A12: FECES HIGH DM FEED - LOW DIGEST | C12: =C11*(100%-$AJ$18)*$AJ$20 -> 0.030365563 | D12: =D11*(100%-$AJ$18)*$AJ$20 -> 0.033174196 | E12: =E11*(100%-$AJ$18)*$AJ$20 -> 0.036289041 | F12: =F11*(100%-$AJ$18)*$AJ$20 -> 0.039619828 | G12: =G11*(100%-$AJ$18)*$AJ$20 -> 0.043085528 | H12: =H11*(100%-$AJ$18)*$AJ$20 -> 0.046821901 | I12: =I11*(100%-$AJ$18)*$AJ$20 -> 0.05086355 | J12: =J11*(100%-$AJ$18)*$AJ$20 -> 0.055124146 | ... AJA12: =AJA11*(100%-$AJ$18)*$AJ$20 -> 0
A13: FECES HIGH DM FEED - HIGH DIGEST | C13: =C11*(100%-$AJ$19)*$AJ$20 -> 0.021689688 | D13: =D11*(100%-$AJ$19)*$AJ$20 -> 0.023695854 | E13: =E11*(100%-$AJ$19)*$AJ$20 -> 0.025920744 | F13: =F11*(100%-$AJ$19)*$AJ$20 -> 0.028299877 | G13: =G11*(100%-$AJ$19)*$AJ$20 -> 0.030775377 | H13: =H11*(100%-$AJ$19)*$AJ$20 -> 0.033444215 | I13: =I11*(100%-$AJ$19)*$AJ$20 -> 0.036331107 | J13: =J11*(100%-$AJ$19)*$AJ$20 -> 0.03937439 | ... AJA13: =AJA11*(100%-$AJ$19)*$AJ$20 -> 0
A15: INITIAL BATCH SIZE | E15: IN | F15: OUT | H15: Year | I15: HARVEST (KG) | J15: FEED (KG) | K15: NaOH (KG) | L15: KOH (KG) | M15: Ca(OH)2 (KG) | N15: # FISH | Q15: MAX STANDING BIOMASS (KG) | R15: MIN STANDING BIOMASS (KG) | S15: MAX DENSITY (KG/M3) | T15: MIN DENSITY (KG/M3) | U15: MEAN DENSITY AT BIOMASS EQUILIBRIUM (KG/M3) | V15: MAX FEED (KG/D) | W15: MAX DAILY RATION AT BIOMASS EQUILIBRIUM (%) | X15: MIN DAILY RATION AT BIOMASS EQUILIBRIUM (%) | Y15: MEAN DAILY RATION AT BIOMASS EQUILIBRIUM (%) | Z15: TEMPERATURE (C°) | AA15: TOTAL HARVEST PER BATCH (KG ROUND FISH) | AB15: MAX AVERAGE FECES DM - HIGH DM FEED (KG/D) | AC15: MIN AVERAGE FECES DM - HIGH DM FEED (KG/D) | AD15: MAX AVERAGE FECES DM - LOW DM FEED (KG/D) | AE15: MIN AVERAGE FECES DM - LOW DM FEED (KG/D) | AJ15: %
A16: =C27 -> 250 | B16: FISH | C16: FISH PER BATCH # | E16: =C27 -> 250 | F16: =EB30+ED30+EI30+EK30+EP30+ER30+EW30+EY30 -> 188.77906 | H16: 1/2 | I16: =SUM(C6:GB6) -> 273.2521 | J16: =SUM(C4:GB4) -> 513.77143 | K16: =SUM(C7:GB7) -> 20.550857 | L16: =K16/40*56 -> 28.7712 | M16: =K16/40*74/2 -> 19.009543 | N16: =C27*4 -> 1000 | AG16: FEED DM LOWER BOUND | AJ16: 0.9
A17: TRANSFER RHYTHM | C17: AVERAGE WEIGHT (KG) | E17: =C33 -> 0.01 | F17: =AVERAGE(EB33,ED33,EI33,EK33,EP33,ER33,EW33,EY33) -> 1.3064381 | H17: 1 | I17: =SUM(C6:NC6) -> 1230.9686 | J17: =SUM(C4:NC4) -> 1296.8735 | K17: =SUM(C7:NC7) -> 51.874942 | L17: =K17/40*56 -> 72.624919 | M17: =K17/40*74/2 -> 47.984321 | N17: =365/A18*C27 -> 1789.2157 | AG17: FEED DM UPPER BOUND | AJ17: 0.95
A18: =COUNT(C1:BA1) -> 51 | B18: DAYS | C18: BIOMASS PER BATCH (KG) | E18: =C34 -> 2.5 | F18: - | H18: 2 | I18: =SUM(ND6:ABD6) -> 1723.356 | J18: =SUM(ND4:ABD4) -> 1505.9587 | K18: =SUM(ND7:ABD7) -> 60.238348 | L18: =K18/40*56 -> 84.333687 | M18: =K18/40*74/2 -> 55.720472 | N18: =365/A18*C27 -> 1789.2157 | P18: Tank 1 | Q18: =MAX(C34:BA34) -> 55.984152 | R18: =MIN(C34:BA34) -> 2.5 | S18: =MAX(C39:BA39) -> 93.306921 | T18: =MIN(C39:BA39) -> 4.1666667 | V18: =MAX(C36:BA36) -> 1.4834504 | Z18: - | AA18: - | AB18: - | AC18: - | AD18: - | AE18: - | AG18: DM DIGESTIBILITY LOWER BOUND | AJ18: 0.65
A19: TIME FROM STOCKING UNTIL FINAL HARVEST | C19: HARVEST PER BATCH (KG) | E19: - | F19: =EB30*EB33+ED30*ED33+EI30*EI33+EK30*EK33+EP30*EP33+ER30*ER33+EW30*EW33+EY30*EY33 -> 246.19372 | P19: Tank 2 + 3 | Q19: =MAX(BB34:CZ34) -> 154.35288 | R19: =MIN(BB34:CZ34) -> 55.872184 | S19: =MAX(BB39:CZ39) -> 128.6274 | T19: =MIN(BB39:CZ39) -> 46.560153 | V19: =MAX(BB36:CZ36) -> 2.1454906 | Z19: - | AA19: - | AB19: - | AC19: - | AD19: - | AE19: - | AG19: DM DIGESTIBILITY UPPER BOUND | AJ19: 0.75
A20: =COUNT(C1:EY1) -> 153 | B20: DAYS | C20: TOTAL FEED PER BATCH (KG) | E20: =SUM(C36:EY36) -> 219.93185 | I20: RANGE AT BIOMASS EQUILIBRIUM | P20: Tank 4 + 5 + 6 | Q20: =MAX(DA34:EY34) -> 213.29087 | R20: =MIN(DA34:EX34) -> 33.904645 | S20: =MAX(DA39:EY39) -> 118.49493 | T20: =MIN(DA39:EX39) -> 18.835914 | V20: =MAX(DA36:EY36) -> 2.4955031 | Z20: - | AG20: MECHANICAL FILTRATION EFFICIENCY | AJ20: 0.65
A21: BATCHES HARVESTED PER YEAR | C21: BATCH eFCR | E21: =E20/F19 -> 0.89332844 | J21: REARING DENSITY TOTAL SYSTEM (KG/M3) | K21: DAILY FEED RATION TOTAL SYSTEM (% OF BIOMASS) | P21: TOTAL System | Q21: =MAX(C2:SZ2) -> 337.00667 | R21: =MIN(EA2:FY2) -> 210.26789 | S21: =MAX(C3:SZ3) -> 93.612964 | T21: =MIN(EA3:FY3) -> 58.407747 | U21: =AVERAGE(EA3:FY3) -> 76.600556 | V21: =MAX(C4:SZ4) -> 5.0606607 | W21: =MAX(EA5:FY5) -> 0.01763313 | X21: =MIN(EA5:EX5,EZ5:FY5) -> 0.0150165 | Y21: =AVERAGE(EA5:FY5) -> 0.015644098 | Z21: 27 | AA21: =F19 -> 246.19372 | AB21: =AVERAGE(EU12:SY12) -> 0.92716542 | AC21: =AVERAGE(EU13:SY13) -> 0.66226101 | AD21: =AVERAGE(EU9:SY9) -> 0.87836724 | AE21: =AVERAGE(EU10:SY10) -> 0.62740517
A22: =365/A18 -> 7.1568627 | B22: Batches | I22: MIN | J22: =T21 -> 58.407747 | K22: =X21 -> 0.0150165
A23: AVERAGE HARVEST PER YEAR AT FULL CAPACITY | I23: MAX | J23: =S21 -> 93.612964 | K23: =W21 -> 0.01763313
A24: =A22*F19 -> 1761.9747 | B24: KG | I24: MEAN | J24: =U21 -> 76.600556 | K24: =Y21 -> 0.015644098
A27: B1 | B27: FISH # | C27: 250 | D27: =C27-C32-D30-D29 -> 249.5 | E27: =D27-D32-E30-E29 -> 249.001 | F27: =E27-E32-F30-F29 -> 248.503 | G27: =F27-F32-G30-G29 -> 248.00599 | H27: =G27-G32-H30-H29 -> 247.50998 | I27: =H27-H32-I30-I29 -> 247.01496 | J27: =I27-I32-J30-J29 -> 246.52093 | K27: =J27-J32-K30-K29 -> 246.02789 | ... EY27: =EX27-EX32-EY30-EY29 -> -0.045955108
B28: OBS MANIP | C28: - | D28: - | E28: - | F28: - | G28: - | H28: - | I28: - | J28: - | K28: - | L28: - | M28: - | N28: - | O28: - | P28: - | Q28: - | R28: - | S28: - | T28: - | U28: - | V28: - | W28: - | X28: - | Y28: - | Z28: - | AA28: - | AB28: - | AC28: - | AD28: - | AE28: - | AF28: - | AG28: - | AH28: - | AI28: - | AJ28: - | AK28: - | AL28: - | AM28: - | AN28: - | AO28: - | AP28: - | AQ28: - | AR28: - | AS28: - | AT28: - | AU28: - | AV28: - | AW28: - | AX28: - | AY28: - | AZ28: - | BA28: - | BB28: - | BC28: - | BD28: - | BE28: - | BF28: - | BG28: - | BH28: - | BI28: - | BJ28: - | BK28: - | BL28: - | BM28: - | BN28: - | BO28: - | BP28: - | BQ28: - | BR28: - | BS28: - | BT28: - | BU28: - | BV28: - | BW28: - | BX28: - | BY28: - | BZ28: - | CA28: - | CB28: - | CC28: - | CD28: - | CE28: - | CF28: - | CG28: - | CH28: - | CI28: - | CJ28: - | CK28: - | CL28: - | CM28: - | CN28: - | CO28: - | CP28: - | CQ28: - | CR28: - | CS28: - | CT28: - | CU28: - | CV28: - | CW28: - | CX28: - | CY28: - | CZ28: - | DA28: - | DB28: - | DC28: - | DD28: - | DE28: - | DF28: - | DG28: - | DH28: - | DI28: - | DJ28: - | DK28: - | DL28: - | DM28: - | DN28: - | DO28: - | DP28: - | DQ28: - | DR28: - | DS28: - | DT28: - | DU28: - | DV28: - | DW28: - | DX28: - | DY28: - | DZ28: - | EA28: - | EB28: Harvest | EC28: - | ED28: Harvest | EE28: - | EF28: - | EG28: - | EH28: - | EI28: Harvest | EJ28: - | EK28: Harvest | EL28: - | EM28: - | EN28: - | EO28: - | EP28: Harvest | EQ28: - | ER28: Harvest | ES28: - | ET28: - | EU28: - | EV28: - | EW28: Harvest | EX28: - | EY28: Harvest
B29: GRADE | C29: 0 | D29: 0 | E29: 0 | F29: 0 | G29: 0 | H29: 0 | I29: 0 | J29: 0 | K29: 0 | L29: 0 | M29: 0 | N29: 0 | O29: 0 | P29: 0 | Q29: 0 | R29: 0 | S29: 0 | T29: 0 | U29: 0 | V29: 0 | W29: 0 | X29: 0 | Y29: 0 | Z29: 0 | AA29: 0 | AB29: 0 | AC29: 0 | AD29: 0 | AE29: 0 | AF29: 0 | AG29: 0 | AH29: 0 | AI29: 0 | AJ29: 0 | AK29: 0 | AL29: 0 | AM29: 0 | AN29: 0 | AO29: 0 | AP29: 0 | AQ29: 0 | AR29: 0 | AS29: 0 | AT29: 0 | AU29: 0 | AV29: 0 | AW29: 0 | AX29: 0 | AY29: 0 | AZ29: 0 | BA29: 0 | BB29: 0 | BC29: 0 | BD29: 0 | BE29: 0 | BF29: 0 | BG29: 0 | BH29: 0 | BI29: 0 | BJ29: 0 | BK29: 0 | BL29: 0 | BM29: 0 | BN29: 0 | BO29: 0 | BP29: 0 | BQ29: 0 | BR29: 0 | BS29: 0 | BT29: 0 | BU29: 0 | BV29: 0 | BW29: 0 | BX29: 0 | BY29: 0 | BZ29: 0 | CA29: 0 | CB29: 0 | CC29: 0 | CD29: 0 | CE29: 0 | CF29: 0 | CG29: 0 | CH29: 0 | CI29: 0 | CJ29: 0 | CK29: 0 | CL29: 0 | CM29: 0 | CN29: 0 | CO29: 0 | CP29: 0 | CQ29: 0 | CR29: 0 | CS29: 0 | CT29: 0 | CU29: 0 | CV29: 0 | CW29: 0 | CX29: 0 | CY29: 0 | CZ29: 0 | DA29: 0 | DB29: 0 | DC29: 0 | DD29: 0 | DE29: 0 | DF29: 0 | DG29: 0 | DH29: 0 | DI29: 0 | DJ29: 0 | DK29: 0 | DL29: 0 | DM29: 0 | DN29: 0 | DO29: 0 | DP29: 0 | DQ29: 0 | DR29: 0 | DS29: 0 | DT29: 0 | DU29: 0 | DV29: 0 | DW29: 0 | DX29: 0 | DY29: 0 | DZ29: 0 | EA29: 0 | EB29: 0 | EC29: 0 | ED29: 0 | EE29: 0 | EF29: 0 | EG29: 0 | EH29: 0 | EI29: 0 | EJ29: 0 | EK29: 0 | EL29: 0 | EM29: 0 | EN29: 0 | EO29: 0 | EP29: 0 | EQ29: 0 | ER29: 0 | ES29: 0 | ET29: 0 | EU29: 0 | EV29: 0 | EW29: 0 | EX29: 0 | EY29: 0
B30: HARVEST # | C30: 0 | D30: 0 | E30: 0 | F30: 0 | G30: 0 | H30: 0 | I30: 0 | J30: 0 | K30: 0 | L30: 0 | M30: 0 | N30: 0 | O30: 0 | P30: 0 | Q30: 0 | R30: 0 | S30: 0 | T30: 0 | U30: 0 | V30: 0 | W30: 0 | X30: 0 | Y30: 0 | Z30: 0 | AA30: 0 | AB30: 0 | AC30: 0 | AD30: 0 | AE30: 0 | AF30: 0 | AG30: 0 | AH30: 0 | AI30: 0 | AJ30: 0 | AK30: 0 | AL30: 0 | AM30: 0 | AN30: 0 | AO30: 0 | AP30: 0 | AQ30: 0 | AR30: 0 | AS30: 0 | AT30: 0 | AU30: 0 | AV30: 0 | AW30: 0 | AX30: 0 | AY30: 0 | AZ30: 0 | BA30: 0 | BB30: 0 | BC30: 0 | BD30: 0 | BE30: 0 | BF30: 0 | BG30: 0 | BH30: 0 | BI30: 0 | BJ30: 0 | BK30: 0 | BL30: 0 | BM30: 0 | BN30: 0 | BO30: 0 | BP30: 0 | BQ30: 0 | BR30: 0 | BS30: 0 | BT30: 0 | BU30: 0 | BV30: 0 | BW30: 0 | BX30: 0 | BY30: 0 | BZ30: 0 | CA30: 0 | CB30: 0 | CC30: 0 | CD30: 0 | CE30: 0 | CF30: 0 | CG30: 0 | CH30: 0 | CI30: 0 | CJ30: 0 | CK30: 0 | CL30: 0 | CM30: 0 | CN30: 0 | CO30: 0 | CP30: 0 | CQ30: 0 | CR30: 0 | CS30: 0 | CT30: 0 | CU30: 0 | CV30: 0 | CW30: 0 | CX30: 0 | CY30: 0 | CZ30: 0 | DA30: 0 | DB30: 0 | DC30: 0 | DD30: 0 | DE30: 0 | DF30: 0 | DG30: 0 | DH30: 0 | DI30: 0 | DJ30: 0 | DK30: 0 | DL30: 0 | DM30: 0 | DN30: 0 | DO30: 0 | DP30: 0 | DQ30: 0 | DR30: 0 | DS30: 0 | DT30: 0 | DU30: 0 | DV30: 0 | DW30: 0 | DX30: 0 | DY30: 0 | DZ30: 0 | EA30: 0 | EB30: =EA27*(1/8) -> 24.185736 | EC30: 0 | ED30: =EC27*(1/7) -> 24.082193 | EE30: 0 | EF30: 0 | EG30: 0 | EH30: 0 | EI30: =EH27*1/6 -> 23.834369 | EJ30: 0 | EK30: =EJ27*(1/5) -> 23.729613 | EL30: 0 | EM30: 0 | EN30: 0 | EO30: 0 | EP30: =EO27*(1/4) -> 23.481494 | EQ30: 0 | ER30: =EQ27*(1/3) -> 23.372038 | ES30: 0 | ET30: 0 | EU30: 0 | EV30: 0 | EW30: =EV27*(1/2) -> 23.116065 | EX30: 0 | EY30: =EX27*1 -> 22.977554
B31: DEAD FISH % | C31: 0.002 | D31: =C31 -> 0.002 | E31: =D31 -> 0.002 | F31: =E31 -> 0.002 | G31: =F31 -> 0.002 | H31: =G31 -> 0.002 | I31: =H31 -> 0.002 | J31: =I31 -> 0.002 | K31: =J31 -> 0.002 | ... EY31: =EX31 -> 0.002
B32: DEAD # | C32: =C31*C27 -> 0.5 | D32: =D31*D27 -> 0.499 | E32: =E31*E27 -> 0.498002 | F32: =F31*F27 -> 0.497006 | G32: =G31*G27 -> 0.49601198 | H32: =H31*H27 -> 0.49501996 | I32: =I31*I27 -> 0.49402992 | J32: =J31*J27 -> 0.49304186 | ... EY32: =EY31*EY27 -> -9.1910216e-05
B33: AVERAGE WEIGHT KG | C33: 0.01 | D33: =C33+((C36/C37)/D27) -> 0.011005583 | E33: =D33+((D36/D37)/E27) -> 0.012106377 | F33: =E33+((E36/E37)/F27) -> 0.013291775 | G33: =F33+((F36/F37)/G27) -> 0.014588567 | H33: =G33+((G36/G37)/H27) -> 0.016001622 | I33: =H33+((H36/H37)/I27) -> 0.017513764 | J33: =I33+((I36/I37)/J27) -> 0.019159727 | K33: =J33+((J36/J37)/K27) -> 0.020916843 | ... EX33: =EW33+((EW36/EW37)/EX27) -> 1.4886426 | EY33: =EX33+((EX36/EX37)/EX27) -> 1.5046616
B34: BM KG | C34: =C27*C33 -> 2.5 | D34: =D27*D33 -> 2.7458929 | E34: =E27*E33 -> 3.0145 | F34: =F27*F33 -> 3.3030458 | G34: =G27*G33 -> 3.6180521 | H34: =H27*H33 -> 3.960561 | I34: =I27*I33 -> 4.3261618 | J34: =J27*J33 -> 4.7232736 | ... EY34: =EY27*EY33 -> -0.069146888
B35: Ration % BM | C35: ='AlltechCoppens_GC_26-28°C'!E179 -> 0.0562 | D35: ='AlltechCoppens_GC_26-28°C'!F179 -> 0.0559 | E35: ='AlltechCoppens_GC_26-28°C'!G179 -> 0.0557 | F35: ='AlltechCoppens_GC_26-28°C'!H179 -> 0.0555 | G35: ='AlltechCoppens_GC_26-28°C'!I179 -> 0.0551 | H35: ='AlltechCoppens_GC_26-28°C'!J179 -> 0.0547 | I35: ='AlltechCoppens_GC_26-28°C'!K179 -> 0.0544 | J35: ='AlltechCoppens_GC_26-28°C'!L179 -> 0.054 | ... EY35: ='AlltechCoppens_GC_26-28°C'!FA179 -> 0.0099
B36: Ration KG/DAY | C36: =C34*C35 -> 0.1405 | D36: =D34*D35 -> 0.15349541 | E36: =E34*E35 -> 0.16790765 | F36: =F34*F35 -> 0.18331904 | G36: =G34*G35 -> 0.19935467 | H36: =H34*H35 -> 0.21664269 | I36: =I34*I35 -> 0.2353432 | J36: =J34*J35 -> 0.25505678 | ... AZ36: =AZ34*AZ35 -> 1.4834504 | BA36: 0 | BB36: =BB34*BB35 -> 1.4638512 | BC36: =BC34*BC35 -> 1.4767759 | BD36: =BD34*BD35 -> 1.4872269 | BE36: =BE34*BE35 -> 1.5080184 | BF36: =BF34*BF35 -> 1.5279257 | BG36: =BG34*BG35 -> 1.5397897 | BH36: =BH34*BH35 -> 1.5567704 | BI36: =BI34*BI35 -> 1.5726898 | ... CY36: =CY34*CY35 -> 2.1454906 | CZ36: 0 | DA36: =DA34*DA35 -> 2.1412141 | DB36: =DB34*DB35 -> 2.1559171 | DC36: =DC34*DC35 -> 2.1703581 | DD36: =DD34*DD35 -> 2.184529 | DE36: =DE34*DE35 -> 2.1984214 | DF36: =DF34*DF35 -> 2.2116333 | DG36: =DG34*DG35 -> 2.2412742 | DH36: =DH34*DH35 -> 2.2543624 | ... EY36: =EY34*EY35 -> -0.00068455419
B37: FCR | C37: ='AlltechCoppens_GC_26-28°C'!E180 -> 0.56 | D37: ='AlltechCoppens_GC_26-28°C'!F180 -> 0.56 | E37: ='AlltechCoppens_GC_26-28°C'!G180 -> 0.57 | F37: ='AlltechCoppens_GC_26-28°C'!H180 -> 0.57 | G37: ='AlltechCoppens_GC_26-28°C'!I180 -> 0.57 | H37: ='AlltechCoppens_GC_26-28°C'!J180 -> 0.58 | I37: ='AlltechCoppens_GC_26-28°C'!K180 -> 0.58 | J37: ='AlltechCoppens_GC_26-28°C'!L180 -> 0.59 | ... EY37: ='AlltechCoppens_GC_26-28°C'!FA180 -> 0.92
B38: SECTION | C38: Tank 1 | D38: Tank 1 | E38: Tank 1 | F38: Tank 1 | G38: Tank 1 | H38: Tank 1 | I38: Tank 1 | J38: Tank 1 | K38: Tank 1 | L38: Tank 1 | M38: Tank 1 | N38: Tank 1 | O38: Tank 1 | P38: Tank 1 | Q38: Tank 1 | R38: Tank 1 | S38: Tank 1 | T38: Tank 1 | U38: Tank 1 | V38: Tank 1 | W38: Tank 1 | X38: Tank 1 | Y38: Tank 1 | Z38: Tank 1 | AA38: Tank 1 | AB38: Tank 1 | AC38: Tank 1 | AD38: Tank 1 | AE38: Tank 1 | AF38: Tank 1 | AG38: Tank 1 | AH38: Tank 1 | AI38: Tank 1 | AJ38: Tank 1 | AK38: Tank 1 | AL38: Tank 1 | AM38: Tank 1 | AN38: Tank 1 | AO38: Tank 1 | AP38: Tank 1 | AQ38: Tank 1 | AR38: Tank 1 | AS38: Tank 1 | AT38: Tank 1 | AU38: Tank 1 | AV38: Tank 1 | AW38: Tank 1 | AX38: Tank 1 | AY38: Tank 1 | AZ38: Tank 1 | BA38: Tank 1 | BB38: Tank 2 + 3 | BC38: Tank 2 + 3 | BD38: Tank 2 + 3 | BE38: Tank 2 + 3 | BF38: Tank 2 + 3 | BG38: Tank 2 + 3 | BH38: Tank 2 + 3 | BI38: Tank 2 + 3 | BJ38: Tank 2 + 3 | BK38: Tank 2 + 3 | BL38: Tank 2 + 3 | BM38: Tank 2 + 3 | BN38: Tank 2 + 3 | BO38: Tank 2 + 3 | BP38: Tank 2 + 3 | BQ38: Tank 2 + 3 | BR38: Tank 2 + 3 | BS38: Tank 2 + 3 | BT38: Tank 2 + 3 | BU38: Tank 2 + 3 | BV38: Tank 2 + 3 | BW38: Tank 2 + 3 | BX38: Tank 2 + 3 | BY38: Tank 2 + 3 | BZ38: Tank 2 + 3 | CA38: Tank 2 + 3 | CB38: Tank 2 + 3 | CC38: Tank 2 + 3 | CD38: Tank 2 + 3 | CE38: Tank 2 + 3 | CF38: Tank 2 + 3 | CG38: Tank 2 + 3 | CH38: Tank 2 + 3 | CI38: Tank 2 + 3 | CJ38: Tank 2 + 3 | CK38: Tank 2 + 3 | CL38: Tank 2 + 3 | CM38: Tank 2 + 3 | CN38: Tank 2 + 3 | CO38: Tank 2 + 3 | CP38: Tank 2 + 3 | CQ38: Tank 2 + 3 | CR38: Tank 2 + 3 | CS38: Tank 2 + 3 | CT38: Tank 2 + 3 | CU38: Tank 2 + 3 | CV38: Tank 2 + 3 | CW38: Tank 2 + 3 | CX38: Tank 2 + 3 | CY38: Tank 2 + 3 | CZ38: Tank 2 + 3 | DA38: Tank 4 + 5 + 6 | DB38: Tank 4 + 5 + 6 | DC38: Tank 4 + 5 + 6 | DD38: Tank 4 + 5 + 6 | DE38: Tank 4 + 5 + 6 | DF38: Tank 4 + 5 + 6 | DG38: Tank 4 + 5 + 6 | DH38: Tank 4 + 5 + 6 | DI38: Tank 4 + 5 + 6 | DJ38: Tank 4 + 5 + 6 | DK38: Tank 4 + 5 + 6 | DL38: Tank 4 + 5 + 6 | DM38: Tank 4 + 5 + 6 | DN38: Tank 4 + 5 + 6 | DO38: Tank 4 + 5 + 6 | DP38: Tank 4 + 5 + 6 | DQ38: Tank 4 + 5 + 6 | DR38: Tank 4 + 5 + 6 | DS38: Tank 4 + 5 + 6 | DT38: Tank 4 + 5 + 6 | DU38: Tank 4 + 5 + 6 | DV38: Tank 4 + 5 + 6 | DW38: Tank 4 + 5 + 6 | DX38: Tank 4 + 5 + 6 | DY38: Tank 4 + 5 + 6 | DZ38: Tank 4 + 5 + 6 | EA38: Tank 4 + 5 + 6 | EB38: Tank 4 + 5 + 6 | EC38: Tank 4 + 5 + 6 | ED38: Tank 4 + 5 + 6 | EE38: Tank 4 + 5 + 6 | EF38: Tank 4 + 5 + 6 | EG38: Tank 4 + 5 + 6 | EH38: Tank 4 + 5 + 6 | EI38: Tank 4 + 5 + 6 | EJ38: Tank 4 + 5 + 6 | EK38: Tank 4 + 5 + 6 | EL38: Tank 4 + 5 + 6 | EM38: Tank 4 + 5 + 6 | EN38: Tank 4 + 5 + 6 | EO38: Tank 4 + 5 + 6 | EP38: Tank 4 + 5 + 6 | EQ38: Tank 4 + 5 + 6 | ER38: Tank 4 + 5 + 6 | ES38: Tank 4 + 5 + 6 | ET38: Tank 4 + 5 + 6 | EU38: Tank 4 + 5 + 6 | EV38: Tank 4 + 5 + 6 | EW38: Tank 4 + 5 + 6 | EX38: Tank 4 + 5 + 6 | EY38: Tank 4 + 5 + 6
B39: DENSITY KG/M3 | C39: =C34/'DATA SECTION'!$C$3 -> 4.1666667 | D39: =D34/'DATA SECTION'!$C$3 -> 4.5764881 | E39: =E34/'DATA SECTION'!$C$3 -> 5.0241667 | F39: =F34/'DATA SECTION'!$C$3 -> 5.5050764 | G39: =G34/'DATA SECTION'!$C$3 -> 6.0300869 | H39: =H34/'DATA SECTION'!$C$3 -> 6.6009351 | I39: =I34/'DATA SECTION'!$C$3 -> 7.2102697 | J39: =J34/'DATA SECTION'!$C$3 -> 7.8721227 | ... BA39: =BA34/'DATA SECTION'!$C$3 -> 93.306921 | BB39: =BB34/'DATA SECTION'!$C$4 -> 46.560153 | BC39: =BC34/'DATA SECTION'!$C$4 -> 48.072133 | BD39: =BD34/'DATA SECTION'!$C$4 -> 49.574231 | BE39: =BE34/'DATA SECTION'!$C$4 -> 51.084636 | BF39: =BF34/'DATA SECTION'!$C$4 -> 52.614521 | BG39: =BG34/'DATA SECTION'!$C$4 -> 54.141691 | BH39: =BH34/'DATA SECTION'!$C$4 -> 55.678482 | BI39: =BI34/'DATA SECTION'!$C$4 -> 57.230341 | ... CZ39: =CZ34/'DATA SECTION'!$C$4 -> 128.6274 | DA39: =DA34/'DATA SECTION'!$C$5 -> 85.580099 | DB39: =DB34/'DATA SECTION'!$C$5 -> 86.792152 | DC39: =DC34/'DATA SECTION'!$C$5 -> 88.011279 | DD39: =DD34/'DATA SECTION'!$C$5 -> 89.237297 | DE39: =DE34/'DATA SECTION'!$C$5 -> 90.470017 | DF39: =DF34/'DATA SECTION'!$C$5 -> 91.692922 | DG39: =DG34/'DATA SECTION'!$C$5 -> 92.921818 | DH39: =DH34/'DATA SECTION'!$C$5 -> 94.167184 | ... EY39: =EY34/'DATA SECTION'!$C$5 -> -0.038414938
A40: B2 | B40: FISH # | BB40: =C27 -> 250 | BC40: =D27 -> 249.5 | BD40: =E27 -> 249.001 | BE40: =F27 -> 248.503 | BF40: =G27 -> 248.00599 | BG40: =H27 -> 247.50998 | BH40: =I27 -> 247.01496 | BI40: =J27 -> 246.52093 | ... GX40: =EY27 -> -0.045955108
B41: OBS MANIP | BB41: =C28 -> - | BC41: =D28 -> - | BD41: =E28 -> - | BE41: =F28 -> - | BF41: =G28 -> - | BG41: =H28 -> - | BH41: =I28 -> - | BI41: =J28 -> - | ... GX41: =EY28 -> Harvest
B42: GRADE | BB42: =C29 -> 0 | BC42: =D29 -> 0 | BD42: =E29 -> 0 | BE42: =F29 -> 0 | BF42: =G29 -> 0 | BG42: =H29 -> 0 | BH42: =I29 -> 0 | BI42: =J29 -> 0 | ... GX42: =EY29 -> 0
B43: HARVEST # | BB43: =C30 -> 0 | BC43: =D30 -> 0 | BD43: =E30 -> 0 | BE43: =F30 -> 0 | BF43: =G30 -> 0 | BG43: =H30 -> 0 | BH43: =I30 -> 0 | BI43: =J30 -> 0 | ... GX43: =EY30 -> 22.977554
...

Sheet DATA SECTION
A1: FishCUBE | E1: MECHANICAL FILTRATION EFFICIENCY
A2: Tanks | C2: Volume (m3) | E2: *Schneider, O., Sereti, V., Eding, E. H., & Verreth, J. A. J. (2005). Analysis of nutrient flows in integrated intensive aquaculture systems. Aquacultural Engineering, 32(3–4), 379–401.
A3: Tank 1 | C3: 0.6
A4: Tank 2 + 3 | C4: =C3*2 -> 1.2
A5: Tank 4 + 5 + 6 | C5: =C3*3 -> 1.8 | E5: APPARENT DRY MATTER DIGESTIBILITY
E6: *Yeo, M. G., Blé, C. M., Otchoumou, A. K., Alla, Y. L., & Etchian, A. O. (2017). Digestibility and growth performance in fingerlings of tilapia Oreochromis niloticus fed with diet containing high-carbohydrate ingredients. 5(4), 171–175.
A8: TILAPIA FEEDING (% BIOMASS/D) | E8: *Palupi, E. T., Setiawati, M., Lumlertdacha, S., & Suprayudi, M. A. (2020). Growth performance, digestibility, and blood biochemical parameters of Nile tilapia (Oreochromis niloticus) reared in floating cages and fed poultry by-product meal. Journal of Applied Aquaculture, 32(1), 16–33.
B9: Aller Performa (2mm) + Bona Float | C9: Aller Performa (2mm) + Primo Float
A10: 10-30 g | B10: 0.0338 | C10: 0.0338 | E10: *Hernández, C., Olvera-Novoa, M. A., Hardy, R. W., Hermosillo, A., Reyes, C., & GonzÁlez, B. (2010). Complete replacement of fish meal by porcine and poultry by-product meals in practical diets for fingerling Nile tilapia Oreochromis niloticus: Digestibility and growth performance. Aquaculture Nutrition, 16(1), 44–53.
A11: 30-70 g | B11: 0.0277 | C11: 0.0278
A12: 70-100 g | B12: 0.0261 | C12: 0.0278
A13: 100-200 g | B13: 0.0208 | C13: 0.0223
A14: 200-400 g | B14: 0.0167 | C14: 0.0178
A15: 400-800 g | B15: 0.0133 | C15: 0.0143
A16: > 800 g | B16: 0.0107 | C16: 0.0114
A19: CLARIAS FEEDING (% BIOMASS/D)
B20: Aller Performa (2 mm) + Claria Float | C20: Bona Float/Claria Float (2 mm) + Bona Float
A21: 10-30 g | B21: 0.049 | C21: 0.0567
A22: 30-50 g | B22: 0.0422 | C22: 0.0482
A23: 50-100 g | B23: 0.0422 | C23: 0.0464
A24: 100-150 g | B24: 0.0341 | C24: 0.0371
A25: 150-300 g | B25: 0.0279 | C25: 0.0297
A26: 300-500 g | B26: 0.0223 | C26: 0.0237
A27: 500-1000 g | B27: 0.0173 | C27: 0.019
A28: 1000-1500 g | B28: 0.0139 | C28: 0.0152
A29: > 1500 g | B29: 0.0112 | C29: 0.0112
A32: CLARIAS FEEDING 26 °C (% BIOMASS/D)
B33: Aller Performa (2 mm) (CP 45% / CF 20%) | C33: Aller Impress Float (2 mm) (CP 50% / CF 15%) | D33: Aller Claria Float (2mm) (CP 45% / CF 12%) | E33: Aller Impress Float (3 mm - CP 48% / CF 13%) (4.5 mm - CP 41 % / CF 13%) | F33: Aller Claria Float (3 mm - CP 45% / CF 12%) (4.5 mm - CP 42 % / CF 12%) (6 mm - CP 40% / CF 12%) | G33: Aller Bona Float (3 mm - CP 42% / CF 12%) (4.5 mm - CP 42 % / CF 12%) (6 mm - CP 42% / CF 12%)
A34: 10-30 g (2mm) | B34: 0.049 | C34: 0.0567 | D34: 0.0567
A35: 30-50 g (2mm) | B35: 0.0422 | C35: 0.0482 | D35: 0.0482
A36: 50-100 g (3 mm) | E36: 0.0421 | F36: 0.0427 | G36: 0.0464
A37: 100-150 g (3 mm) | E37: 0.0337 | F37: 0.0341 | G37: 0.0371
A38: 150-300 g (4.5 mm) | E38: 0.0282 | F38: 0.0279 | G38: 0.0297
A39: 300-500 g (4.5 mm) | E39: 0.0226 | F39: 0.0223 | G39: 0.0237
A40: 500-1000 g (4.5 mm) | E40: 0.018 | F40: 0.0173 | G40: 0.019
A41: 1000-1500 g (4.5 mm) | E41: 0.0144 | F41: 0.0139 | G41: 0.0152
A42: > 1500 g
O45: 150 | P45: 160 | Q45: 170 | R45: 180 | S45: 190 | T45: 200 | U45: 210 | V45: 220 | W45: 230 | X45: 240 | Y45: 250 | Z45: 260 | AA45: 270 | AB45: 280 | AC45: 290 | AD45: 300 | AE45: 310 | AF45: 320 | AG45: 330 | AH45: 340 | AI45: 350 | AJ45: 360 | AK45: 370 | AL45: 380 | AM45: 390 | AN45: 400 | AO45: 410 | AP45: 420 | AQ45: 430 | AR45: 440 | AS45: 450 | AT45: 460 | AU45: 470 | AV45: 480 | AW45: 490 | AX45: 500 | AY45: 510 | AZ45: 520 | BA45: 530 | BB45: 540 | BC45: 550 | BD45: 560 | BE45: 570 | BF45: 580 | BG45: 590 | BH45: 600 | BI45: 610 | BJ45: 620 | BK45: 630 | BL45: 640 | BM45: 650 | BN45: 660 | BO45: 670 | BP45: 680 | BQ45: 690 | BR45: 700 | BS45: 710 | BT45: 720 | BU45: 730 | BV45: 740 | BW45: 750 | BX45: 760 | BY45: 770 | BZ45: 780 | CA45: 790 | CB45: 800 | CC45: 810 | CD45: 820 | CE45: 830 | CF45: 840 | CG45: 850 | CH45: 860 | CI45: 870 | CJ45: 880 | CK45: 890 | CL45: 900 | CM45: 910 | CN45: 920 | CO45: 930 | CP45: 940 | CQ45: 950 | CR45: 960 | CS45: 970 | CT45: 980 | CU45: 990 | CV45: 1000 | CW45: 1010 | CX45: 1020 | CY45: 1030 | CZ45: 1040 | DA45: 1050 | DB45: 1060 | DC45: 1070 | DD45: 1080 | DE45: 1090 | DF45: 1100 | DG45: 1110 | DH45: 1120 | DI45: 1130 | DJ45: 1140 | DK45: 1150 | DL45: 1160 | DM45: 1170 | DN45: 1180 | DO45: 1190 | DP45: 1200 | DQ45: 1210 | DR45: 1220 | DS45: 1230 | DT45: 1240 | DU45: 1250 | DV45: 1260 | DW45: 1270 | DX45: 1280 | DY45: 1290 | DZ45: 1300 | EA45: 1310 | EB45: 1320 | EC45: 1330 | ED45: 1340 | EE45: 1350 | EF45: 1360 | EG45: 1370 | EH45: 1380 | EI45: 1390 | EJ45: 1400 | EK45: 1410 | EL45: 1420 | EM45: 1430 | EN45: 1440 | EO45: 1450 | EP45: 1460 | EQ45: 1470 | ER45: 1480 | ES45: 1490 | ET45: 1500

Sheet AlltechCoppens_GC_26-28°C
A1: Day | B1: Fish weight (g) | C1: Feeding level (% BW/day) | D1: FCR | E1: SGR (% BW/day) | F1: Feed type
A2: 0 | B2: 7.5 | C2: 0.0568 | D2: 0.55 | E2: 0.104 | F2: Advance (1.5mm)
A3: 1 | B3: 8.3 | C3: 0.0566 | D3: 0.55 | E3: 0.103 | F3: "
A4: 2 | B4: 9.1 | C4: 0.0564 | D4: 0.55 | E4: 0.102 | F4: "
A5: 3 | B5: 10.1 | C5: 0.0562 | D5: 0.56 | E5: 0.101 | F5: "
A6: 4 | B6: 11.1 | C6: 0.0559 | D6: 0.56 | E6: 0.1 | F6: "
A7: 5 | B7: 12.2 | C7: 0.0557 | D7: 0.57 | E7: 0.099 | F7: "
A8: 6 | B8: 13.4 | C8: 0.0555 | D8: 0.57 | E8: 0.098 | F8: Pregrower-15 EF (2mm)
A9: 7 | B9: 14.7 | C9: 0.0551 | D9: 0.57 | E9: 0.096 | F9: "
A10: 8 | B10: 16.1 | C10: 0.0547 | D10: 0.58 | E10: 0.095 | F10: "
A11: 9 | B11: 17.7 | C11: 0.0544 | D11: 0.58 | E11: 0.094 | F11: "
A12: 10 | B12: 19.3 | C12: 0.054 | D12: 0.59 | E12: 0.092 | F12: "
A13: 11 | B13: 21.1 | C13: 0.0536 | D13: 0.59 | E13: 0.091 | F13: "
... A60: 58 | B60: 296 | C60: 0.0242 | D60: 0.78 | E60: 0.031 | F60: "
A61: 59 | B61: 305 | C61: 0.0237 | D61: 0.78 | E61: 0.031 | F61: "
A62: 60 | B62: 314 | C62: 0.0233 | D62: 0.78 | E62: 0.03 | F62: "
A63: 61 | B63: 324 | C63: 0.0229 | D63: 0.78 | E63: 0.029 | F63: "
A64: 62 | B64: 333 | C64: 0.0225 | D64: 0.79 | E64: 0.029 | F64: "
A65: 63 | B65: 343 | C65: 0.0221 | D65: 0.79 | E65: 0.028 | F65: "
A66: 64 | B66: 352 | C66: 0.0216 | D66: 0.79 | E66: 0.027 | F66: "
A67: 65 | B67: 362 | C67: 0.0212 | D67: 0.79 | E67: 0.027 | F67: "
A68: 66 | B68: 372 | C68: 0.0208 | D68: 0.8 | E68: 0.026 | F68: "
A69: 67 | B69: 382 | C69: 0.0205 | D69: 0.8 | E69: 0.026 | F69: "
A70: 68 | B70: 391 | C70: 0.0202 | D70: 0.8 | E70: 0.025 | F70: "
A71: 69 | B71: 401 | C71: 0.0199 | D71: 0.8 | E71: 0.025 | F71: "
A72: 70 | B72: 411 | C72: 0.0196 | D72: 0.8 | E72: 0.024 | F72: "
... A126: 124 | B126: 1069 | C126: 0.0123 | D126: 0.89 | E126: 0.014 | F126: "
A127: 125 | B127: 1084 | C127: 0.0122 | D127: 0.89 | E127: 0.014 | F127: "
A128: 126 | B128: 1099 | C128: 0.0121 | D128: 0.89 | E128: 0.014 | F128: "
A129: 127 | B129: 1114 | C129: 0.012 | D129: 0.89 | E129: 0.013 | F129: "
A130: 128 | B130: 1129 | C130: 0.0119 | D130: 0.89 | E130: 0.013 | F130: "
A131: 129 | B131: 1144 | C131: 0.0118 | D131: 0.89 | E131: 0.013 | F131: "
A132: 130 | B132: 1159 | C132: 0.0117 | D132: 0.9 | E132: 0.013 | F132: "
A133: 131 | B133: 1174 | C133: 0.0117 | D133: 0.9 | E133: 0.013 | F133: "
A134: 132 | B134: 1189 | C134: 0.0116 | D134: 0.9 | E134: 0.013 | F134: "
A135: 133 | B135: 1205 | C135: 0.0115 | D135: 0.9 | E135: 0.013 | F135: "
A136: 134 | B136: 1220 | C136: 0.0114 | D136: 0.9 | E136: 0.013 | F136: "
A137: 135 | B137: 1236 | C137: 0.0113 | D137: 0.9 | E137: 0.013 | F137: "
A138: 136 | B138: 1251 | C138: 0.0112 | D138: 0.9 | E138: 0.012 | F138: "
... A172: 170 | B172: 1808 | C172: 0.0089 | D172: 0.94 | E172: 0.01 | F172: "
...
